2025-07-10 17:20:45,815 - ERROR - Unhandled exception: Traceback (most recent call last):
  File "/home/tamara/Sws/senpwai/.venv/lib/python3.13/site-packages/senpwai/windows/download.py", line 1168, in run
    self.anime_details.ddls_or_segs_urls = obj.get_direct_download_links(
                                           ~~~~~~~~~~~~~~~~~~~~~~~~~~~~~^
        bound_links, lambda x: self.update_bar.emit(x)
        ^^^^^^^^^^^^^^^^^^^^^^^^^^^^^^^^^^^^^^^^^^^^^^
    )
    ^
  File "/home/tamara/Sws/senpwai/.venv/lib/python3.13/site-packages/senpwai/scrapers/pahe/main.py", line 338, in get_direct_download_links
    match.group(1),
    ^^^^^^^^^^^
AttributeError: 'NoneType' object has no attribute 'group'
-----------------------------------------------------------------------------------------------------------------------------

2025-07-10 18:34:54,149 - ERROR - Exception: Traceback (most recent call last):
  File "/home/tamara/Sws/senpwai/.venv/lib/python3.13/site-packages/urllib3/response.py", line 779, in _error_catcher
    yield
  File "/home/tamara/Sws/senpwai/.venv/lib/python3.13/site-packages/urllib3/response.py", line 904, in _raw_read
    data = self._fp_read(amt, read1=read1) if not fp_closed else b""
           ~~~~~~~~~~~~~^^^^^^^^^^^^^^^^^^
  File "/home/tamara/Sws/senpwai/.venv/lib/python3.13/site-packages/urllib3/response.py", line 887, in _fp_read
    return self._fp.read(amt) if amt is not None else self._fp.read()
           ~~~~~~~~~~~~~^^^^^
  File "/usr/lib/python3.13/http/client.py", line 479, in read
    s = self.fp.read(amt)
  File "/usr/lib/python3.13/socket.py", line 719, in readinto
    return self._sock.recv_into(b)
           ~~~~~~~~~~~~~~~~~~~~^^^
  File "/usr/lib/python3.13/ssl.py", line 1304, in recv_into
    return self.read(nbytes, buffer)
           ~~~~~~~~~^^^^^^^^^^^^^^^^
  File "/usr/lib/python3.13/ssl.py", line 1138, in read
    return self._sslobj.read(len, buffer)
           ~~~~~~~~~~~~~~~~~^^^^^^^^^^^^^
TimeoutError: The read operation timed out

The above exception was the direct cause of the following exception:

Traceback (most recent call last):
  File "/home/tamara/Sws/senpwai/.venv/lib/python3.13/site-packages/requests/models.py", line 820, in generate
    yield from self.raw.stream(chunk_size, decode_content=True)
  File "/home/tamara/Sws/senpwai/.venv/lib/python3.13/site-packages/urllib3/response.py", line 1091, in stream
    data = self.read(amt=amt, decode_content=decode_content)
  File "/home/tamara/Sws/senpwai/.venv/lib/python3.13/site-packages/urllib3/response.py", line 980, in read
    data = self._raw_read(amt)
  File "/home/tamara/Sws/senpwai/.venv/lib/python3.13/site-packages/urllib3/response.py", line 903, in _raw_read
    with self._error_catcher():
         ~~~~~~~~~~~~~~~~~~~^^
  File "/usr/lib/python3.13/contextlib.py", line 162, in __exit__
    self.gen.throw(value)
    ~~~~~~~~~~~~~~^^^^^^^
  File "/home/tamara/Sws/senpwai/.venv/lib/python3.13/site-packages/urllib3/response.py", line 784, in _error_catcher
    raise ReadTimeoutError(self._pool, None, "Read timed out.") from e  # type: ignore[arg-type]
    ^^^^^^^^^^^^^^^^^^^^^^^^^^^^^^^^^^^^^^^^^^^^^^^^^^^^^^^^^^^^^^^^^^
urllib3.exceptions.ReadTimeoutError: HTTPSConnectionPool(host='eu-02.nextcdn.org', port=443): Read timed out.

During handling of the above exception, another exception occurred:

Traceback (most recent call last):
  File "/home/tamara/Sws/senpwai/.venv/lib/python3.13/site-packages/senpwai/common/scraper.py", line 229, in network_error_retry_wrapper
    return callback()
  File "/home/tamara/Sws/senpwai/.venv/lib/python3.13/site-packages/senpwai/common/scraper.py", line 558, in <lambda>
    lambda: next(iter_content)
            ~~~~^^^^^^^^^^^^^^
  File "/home/tamara/Sws/senpwai/.venv/lib/python3.13/site-packages/requests/models.py", line 826, in generate
    raise ConnectionError(e)
requests.exceptions.ConnectionError: HTTPSConnectionPool(host='eu-02.nextcdn.org', port=443): Read timed out.
-----------------------------------------------------------------------------------------------------------------------------

2025-07-10 18:43:58,690 - ERROR - Exception: Traceback (most recent call last):
  File "/home/tamara/Sws/senpwai/.venv/lib/python3.13/site-packages/urllib3/response.py", line 779, in _error_catcher
    yield
  File "/home/tamara/Sws/senpwai/.venv/lib/python3.13/site-packages/urllib3/response.py", line 904, in _raw_read
    data = self._fp_read(amt, read1=read1) if not fp_closed else b""
           ~~~~~~~~~~~~~^^^^^^^^^^^^^^^^^^
  File "/home/tamara/Sws/senpwai/.venv/lib/python3.13/site-packages/urllib3/response.py", line 887, in _fp_read
    return self._fp.read(amt) if amt is not None else self._fp.read()
           ~~~~~~~~~~~~~^^^^^
  File "/usr/lib/python3.13/http/client.py", line 479, in read
    s = self.fp.read(amt)
  File "/usr/lib/python3.13/socket.py", line 719, in readinto
    return self._sock.recv_into(b)
           ~~~~~~~~~~~~~~~~~~~~^^^
  File "/usr/lib/python3.13/ssl.py", line 1304, in recv_into
    return self.read(nbytes, buffer)
           ~~~~~~~~~^^^^^^^^^^^^^^^^
  File "/usr/lib/python3.13/ssl.py", line 1138, in read
    return self._sslobj.read(len, buffer)
           ~~~~~~~~~~~~~~~~~^^^^^^^^^^^^^
ConnectionResetError: [Errno 104] Connection reset by peer

The above exception was the direct cause of the following exception:

Traceback (most recent call last):
  File "/home/tamara/Sws/senpwai/.venv/lib/python3.13/site-packages/requests/models.py", line 820, in generate
    yield from self.raw.stream(chunk_size, decode_content=True)
  File "/home/tamara/Sws/senpwai/.venv/lib/python3.13/site-packages/urllib3/response.py", line 1091, in stream
    data = self.read(amt=amt, decode_content=decode_content)
  File "/home/tamara/Sws/senpwai/.venv/lib/python3.13/site-packages/urllib3/response.py", line 980, in read
    data = self._raw_read(amt)
  File "/home/tamara/Sws/senpwai/.venv/lib/python3.13/site-packages/urllib3/response.py", line 903, in _raw_read
    with self._error_catcher():
         ~~~~~~~~~~~~~~~~~~~^^
  File "/usr/lib/python3.13/contextlib.py", line 162, in __exit__
    self.gen.throw(value)
    ~~~~~~~~~~~~~~^^^^^^^
  File "/home/tamara/Sws/senpwai/.venv/lib/python3.13/site-packages/urllib3/response.py", line 806, in _error_catcher
    raise ProtocolError(f"Connection broken: {e!r}", e) from e
urllib3.exceptions.ProtocolError: ("Connection broken: ConnectionResetError(104, 'Connection reset by peer')", ConnectionResetError(104, 'Connection reset by peer'))

During handling of the above exception, another exception occurred:

Traceback (most recent call last):
  File "/home/tamara/Sws/senpwai/.venv/lib/python3.13/site-packages/senpwai/common/scraper.py", line 229, in network_error_retry_wrapper
    return callback()
  File "/home/tamara/Sws/senpwai/.venv/lib/python3.13/site-packages/senpwai/common/scraper.py", line 558, in <lambda>
    lambda: next(iter_content)
            ~~~~^^^^^^^^^^^^^^
  File "/home/tamara/Sws/senpwai/.venv/lib/python3.13/site-packages/requests/models.py", line 822, in generate
    raise ChunkedEncodingError(e)
requests.exceptions.ChunkedEncodingError: ("Connection broken: ConnectionResetError(104, 'Connection reset by peer')", ConnectionResetError(104, 'Connection reset by peer'))
-----------------------------------------------------------------------------------------------------------------------------

2025-07-10 18:50:11,544 - ERROR - Exception: Traceback (most recent call last):
  File "/home/tamara/Sws/senpwai/.venv/lib/python3.13/site-packages/urllib3/response.py", line 779, in _error_catcher
    yield
  File "/home/tamara/Sws/senpwai/.venv/lib/python3.13/site-packages/urllib3/response.py", line 904, in _raw_read
    data = self._fp_read(amt, read1=read1) if not fp_closed else b""
           ~~~~~~~~~~~~~^^^^^^^^^^^^^^^^^^
  File "/home/tamara/Sws/senpwai/.venv/lib/python3.13/site-packages/urllib3/response.py", line 887, in _fp_read
    return self._fp.read(amt) if amt is not None else self._fp.read()
           ~~~~~~~~~~~~~^^^^^
  File "/usr/lib/python3.13/http/client.py", line 479, in read
    s = self.fp.read(amt)
  File "/usr/lib/python3.13/socket.py", line 719, in readinto
    return self._sock.recv_into(b)
           ~~~~~~~~~~~~~~~~~~~~^^^
  File "/usr/lib/python3.13/ssl.py", line 1304, in recv_into
    return self.read(nbytes, buffer)
           ~~~~~~~~~^^^^^^^^^^^^^^^^
  File "/usr/lib/python3.13/ssl.py", line 1138, in read
    return self._sslobj.read(len, buffer)
           ~~~~~~~~~~~~~~~~~^^^^^^^^^^^^^
ConnectionResetError: [Errno 104] Connection reset by peer

The above exception was the direct cause of the following exception:

Traceback (most recent call last):
  File "/home/tamara/Sws/senpwai/.venv/lib/python3.13/site-packages/requests/models.py", line 820, in generate
    yield from self.raw.stream(chunk_size, decode_content=True)
  File "/home/tamara/Sws/senpwai/.venv/lib/python3.13/site-packages/urllib3/response.py", line 1091, in stream
    data = self.read(amt=amt, decode_content=decode_content)
  File "/home/tamara/Sws/senpwai/.venv/lib/python3.13/site-packages/urllib3/response.py", line 980, in read
    data = self._raw_read(amt)
  File "/home/tamara/Sws/senpwai/.venv/lib/python3.13/site-packages/urllib3/response.py", line 903, in _raw_read
    with self._error_catcher():
         ~~~~~~~~~~~~~~~~~~~^^
  File "/usr/lib/python3.13/contextlib.py", line 162, in __exit__
    self.gen.throw(value)
    ~~~~~~~~~~~~~~^^^^^^^
  File "/home/tamara/Sws/senpwai/.venv/lib/python3.13/site-packages/urllib3/response.py", line 806, in _error_catcher
    raise ProtocolError(f"Connection broken: {e!r}", e) from e
urllib3.exceptions.ProtocolError: ("Connection broken: ConnectionResetError(104, 'Connection reset by peer')", ConnectionResetError(104, 'Connection reset by peer'))

During handling of the above exception, another exception occurred:

Traceback (most recent call last):
  File "/home/tamara/Sws/senpwai/.venv/lib/python3.13/site-packages/senpwai/common/scraper.py", line 229, in network_error_retry_wrapper
    return callback()
  File "/home/tamara/Sws/senpwai/.venv/lib/python3.13/site-packages/senpwai/common/scraper.py", line 558, in <lambda>
    lambda: next(iter_content)
            ~~~~^^^^^^^^^^^^^^
  File "/home/tamara/Sws/senpwai/.venv/lib/python3.13/site-packages/requests/models.py", line 822, in generate
    raise ChunkedEncodingError(e)
requests.exceptions.ChunkedEncodingError: ("Connection broken: ConnectionResetError(104, 'Connection reset by peer')", ConnectionResetError(104, 'Connection reset by peer'))
-----------------------------------------------------------------------------------------------------------------------------

2025-07-10 18:52:27,956 - ERROR - Exception: Traceback (most recent call last):
  File "/home/tamara/Sws/senpwai/.venv/lib/python3.13/site-packages/urllib3/response.py", line 779, in _error_catcher
    yield
  File "/home/tamara/Sws/senpwai/.venv/lib/python3.13/site-packages/urllib3/response.py", line 904, in _raw_read
    data = self._fp_read(amt, read1=read1) if not fp_closed else b""
           ~~~~~~~~~~~~~^^^^^^^^^^^^^^^^^^
  File "/home/tamara/Sws/senpwai/.venv/lib/python3.13/site-packages/urllib3/response.py", line 887, in _fp_read
    return self._fp.read(amt) if amt is not None else self._fp.read()
           ~~~~~~~~~~~~~^^^^^
  File "/usr/lib/python3.13/http/client.py", line 479, in read
    s = self.fp.read(amt)
  File "/usr/lib/python3.13/socket.py", line 719, in readinto
    return self._sock.recv_into(b)
           ~~~~~~~~~~~~~~~~~~~~^^^
  File "/usr/lib/python3.13/ssl.py", line 1304, in recv_into
    return self.read(nbytes, buffer)
           ~~~~~~~~~^^^^^^^^^^^^^^^^
  File "/usr/lib/python3.13/ssl.py", line 1138, in read
    return self._sslobj.read(len, buffer)
           ~~~~~~~~~~~~~~~~~^^^^^^^^^^^^^
TimeoutError: The read operation timed out

The above exception was the direct cause of the following exception:

Traceback (most recent call last):
  File "/home/tamara/Sws/senpwai/.venv/lib/python3.13/site-packages/requests/models.py", line 820, in generate
    yield from self.raw.stream(chunk_size, decode_content=True)
  File "/home/tamara/Sws/senpwai/.venv/lib/python3.13/site-packages/urllib3/response.py", line 1091, in stream
    data = self.read(amt=amt, decode_content=decode_content)
  File "/home/tamara/Sws/senpwai/.venv/lib/python3.13/site-packages/urllib3/response.py", line 980, in read
    data = self._raw_read(amt)
  File "/home/tamara/Sws/senpwai/.venv/lib/python3.13/site-packages/urllib3/response.py", line 903, in _raw_read
    with self._error_catcher():
         ~~~~~~~~~~~~~~~~~~~^^
  File "/usr/lib/python3.13/contextlib.py", line 162, in __exit__
    self.gen.throw(value)
    ~~~~~~~~~~~~~~^^^^^^^
  File "/home/tamara/Sws/senpwai/.venv/lib/python3.13/site-packages/urllib3/response.py", line 784, in _error_catcher
    raise ReadTimeoutError(self._pool, None, "Read timed out.") from e  # type: ignore[arg-type]
    ^^^^^^^^^^^^^^^^^^^^^^^^^^^^^^^^^^^^^^^^^^^^^^^^^^^^^^^^^^^^^^^^^^
urllib3.exceptions.ReadTimeoutError: HTTPSConnectionPool(host='eu-02.nextcdn.org', port=443): Read timed out.

During handling of the above exception, another exception occurred:

Traceback (most recent call last):
  File "/home/tamara/Sws/senpwai/.venv/lib/python3.13/site-packages/senpwai/common/scraper.py", line 229, in network_error_retry_wrapper
    return callback()
  File "/home/tamara/Sws/senpwai/.venv/lib/python3.13/site-packages/senpwai/common/scraper.py", line 558, in <lambda>
    lambda: next(iter_content)
            ~~~~^^^^^^^^^^^^^^
  File "/home/tamara/Sws/senpwai/.venv/lib/python3.13/site-packages/requests/models.py", line 826, in generate
    raise ConnectionError(e)
requests.exceptions.ConnectionError: HTTPSConnectionPool(host='eu-02.nextcdn.org', port=443): Read timed out.
-----------------------------------------------------------------------------------------------------------------------------

2025-07-10 19:01:40,500 - ERROR - Exception: Traceback (most recent call last):
  File "/home/tamara/Sws/senpwai/.venv/lib/python3.13/site-packages/urllib3/response.py", line 779, in _error_catcher
    yield
  File "/home/tamara/Sws/senpwai/.venv/lib/python3.13/site-packages/urllib3/response.py", line 904, in _raw_read
    data = self._fp_read(amt, read1=read1) if not fp_closed else b""
           ~~~~~~~~~~~~~^^^^^^^^^^^^^^^^^^
  File "/home/tamara/Sws/senpwai/.venv/lib/python3.13/site-packages/urllib3/response.py", line 887, in _fp_read
    return self._fp.read(amt) if amt is not None else self._fp.read()
           ~~~~~~~~~~~~~^^^^^
  File "/usr/lib/python3.13/http/client.py", line 479, in read
    s = self.fp.read(amt)
  File "/usr/lib/python3.13/socket.py", line 719, in readinto
    return self._sock.recv_into(b)
           ~~~~~~~~~~~~~~~~~~~~^^^
  File "/usr/lib/python3.13/ssl.py", line 1304, in recv_into
    return self.read(nbytes, buffer)
           ~~~~~~~~~^^^^^^^^^^^^^^^^
  File "/usr/lib/python3.13/ssl.py", line 1138, in read
    return self._sslobj.read(len, buffer)
           ~~~~~~~~~~~~~~~~~^^^^^^^^^^^^^
ConnectionResetError: [Errno 104] Connection reset by peer

The above exception was the direct cause of the following exception:

Traceback (most recent call last):
  File "/home/tamara/Sws/senpwai/.venv/lib/python3.13/site-packages/requests/models.py", line 820, in generate
    yield from self.raw.stream(chunk_size, decode_content=True)
  File "/home/tamara/Sws/senpwai/.venv/lib/python3.13/site-packages/urllib3/response.py", line 1091, in stream
    data = self.read(amt=amt, decode_content=decode_content)
  File "/home/tamara/Sws/senpwai/.venv/lib/python3.13/site-packages/urllib3/response.py", line 980, in read
    data = self._raw_read(amt)
  File "/home/tamara/Sws/senpwai/.venv/lib/python3.13/site-packages/urllib3/response.py", line 903, in _raw_read
    with self._error_catcher():
         ~~~~~~~~~~~~~~~~~~~^^
  File "/usr/lib/python3.13/contextlib.py", line 162, in __exit__
    self.gen.throw(value)
    ~~~~~~~~~~~~~~^^^^^^^
  File "/home/tamara/Sws/senpwai/.venv/lib/python3.13/site-packages/urllib3/response.py", line 806, in _error_catcher
    raise ProtocolError(f"Connection broken: {e!r}", e) from e
urllib3.exceptions.ProtocolError: ("Connection broken: ConnectionResetError(104, 'Connection reset by peer')", ConnectionResetError(104, 'Connection reset by peer'))

During handling of the above exception, another exception occurred:

Traceback (most recent call last):
  File "/home/tamara/Sws/senpwai/.venv/lib/python3.13/site-packages/senpwai/common/scraper.py", line 229, in network_error_retry_wrapper
    return callback()
  File "/home/tamara/Sws/senpwai/.venv/lib/python3.13/site-packages/senpwai/common/scraper.py", line 558, in <lambda>
    lambda: next(iter_content)
            ~~~~^^^^^^^^^^^^^^
  File "/home/tamara/Sws/senpwai/.venv/lib/python3.13/site-packages/requests/models.py", line 822, in generate
    raise ChunkedEncodingError(e)
requests.exceptions.ChunkedEncodingError: ("Connection broken: ConnectionResetError(104, 'Connection reset by peer')", ConnectionResetError(104, 'Connection reset by peer'))
-----------------------------------------------------------------------------------------------------------------------------

2025-07-10 19:07:54,751 - ERROR - Exception: Traceback (most recent call last):
  File "/home/tamara/Sws/senpwai/.venv/lib/python3.13/site-packages/urllib3/response.py", line 779, in _error_catcher
    yield
  File "/home/tamara/Sws/senpwai/.venv/lib/python3.13/site-packages/urllib3/response.py", line 904, in _raw_read
    data = self._fp_read(amt, read1=read1) if not fp_closed else b""
           ~~~~~~~~~~~~~^^^^^^^^^^^^^^^^^^
  File "/home/tamara/Sws/senpwai/.venv/lib/python3.13/site-packages/urllib3/response.py", line 887, in _fp_read
    return self._fp.read(amt) if amt is not None else self._fp.read()
           ~~~~~~~~~~~~~^^^^^
  File "/usr/lib/python3.13/http/client.py", line 479, in read
    s = self.fp.read(amt)
  File "/usr/lib/python3.13/socket.py", line 719, in readinto
    return self._sock.recv_into(b)
           ~~~~~~~~~~~~~~~~~~~~^^^
  File "/usr/lib/python3.13/ssl.py", line 1304, in recv_into
    return self.read(nbytes, buffer)
           ~~~~~~~~~^^^^^^^^^^^^^^^^
  File "/usr/lib/python3.13/ssl.py", line 1138, in read
    return self._sslobj.read(len, buffer)
           ~~~~~~~~~~~~~~~~~^^^^^^^^^^^^^
TimeoutError: The read operation timed out

The above exception was the direct cause of the following exception:

Traceback (most recent call last):
  File "/home/tamara/Sws/senpwai/.venv/lib/python3.13/site-packages/requests/models.py", line 820, in generate
    yield from self.raw.stream(chunk_size, decode_content=True)
  File "/home/tamara/Sws/senpwai/.venv/lib/python3.13/site-packages/urllib3/response.py", line 1091, in stream
    data = self.read(amt=amt, decode_content=decode_content)
  File "/home/tamara/Sws/senpwai/.venv/lib/python3.13/site-packages/urllib3/response.py", line 980, in read
    data = self._raw_read(amt)
  File "/home/tamara/Sws/senpwai/.venv/lib/python3.13/site-packages/urllib3/response.py", line 903, in _raw_read
    with self._error_catcher():
         ~~~~~~~~~~~~~~~~~~~^^
  File "/usr/lib/python3.13/contextlib.py", line 162, in __exit__
    self.gen.throw(value)
    ~~~~~~~~~~~~~~^^^^^^^
  File "/home/tamara/Sws/senpwai/.venv/lib/python3.13/site-packages/urllib3/response.py", line 784, in _error_catcher
    raise ReadTimeoutError(self._pool, None, "Read timed out.") from e  # type: ignore[arg-type]
    ^^^^^^^^^^^^^^^^^^^^^^^^^^^^^^^^^^^^^^^^^^^^^^^^^^^^^^^^^^^^^^^^^^
urllib3.exceptions.ReadTimeoutError: HTTPSConnectionPool(host='eu-01.nextcdn.org', port=443): Read timed out.

During handling of the above exception, another exception occurred:

Traceback (most recent call last):
  File "/home/tamara/Sws/senpwai/.venv/lib/python3.13/site-packages/senpwai/common/scraper.py", line 229, in network_error_retry_wrapper
    return callback()
  File "/home/tamara/Sws/senpwai/.venv/lib/python3.13/site-packages/senpwai/common/scraper.py", line 558, in <lambda>
    lambda: next(iter_content)
            ~~~~^^^^^^^^^^^^^^
  File "/home/tamara/Sws/senpwai/.venv/lib/python3.13/site-packages/requests/models.py", line 826, in generate
    raise ConnectionError(e)
requests.exceptions.ConnectionError: HTTPSConnectionPool(host='eu-01.nextcdn.org', port=443): Read timed out.
-----------------------------------------------------------------------------------------------------------------------------

2025-07-10 19:52:10,622 - ERROR - Exception: Traceback (most recent call last):
  File "/home/tamara/Sws/senpwai/.venv/lib/python3.13/site-packages/urllib3/response.py", line 779, in _error_catcher
    yield
  File "/home/tamara/Sws/senpwai/.venv/lib/python3.13/site-packages/urllib3/response.py", line 904, in _raw_read
    data = self._fp_read(amt, read1=read1) if not fp_closed else b""
           ~~~~~~~~~~~~~^^^^^^^^^^^^^^^^^^
  File "/home/tamara/Sws/senpwai/.venv/lib/python3.13/site-packages/urllib3/response.py", line 887, in _fp_read
    return self._fp.read(amt) if amt is not None else self._fp.read()
           ~~~~~~~~~~~~~^^^^^
  File "/usr/lib/python3.13/http/client.py", line 479, in read
    s = self.fp.read(amt)
  File "/usr/lib/python3.13/socket.py", line 719, in readinto
    return self._sock.recv_into(b)
           ~~~~~~~~~~~~~~~~~~~~^^^
  File "/usr/lib/python3.13/ssl.py", line 1304, in recv_into
    return self.read(nbytes, buffer)
           ~~~~~~~~~^^^^^^^^^^^^^^^^
  File "/usr/lib/python3.13/ssl.py", line 1138, in read
    return self._sslobj.read(len, buffer)
           ~~~~~~~~~~~~~~~~~^^^^^^^^^^^^^
ConnectionResetError: [Errno 104] Connection reset by peer

The above exception was the direct cause of the following exception:

Traceback (most recent call last):
  File "/home/tamara/Sws/senpwai/.venv/lib/python3.13/site-packages/requests/models.py", line 820, in generate
    yield from self.raw.stream(chunk_size, decode_content=True)
  File "/home/tamara/Sws/senpwai/.venv/lib/python3.13/site-packages/urllib3/response.py", line 1091, in stream
    data = self.read(amt=amt, decode_content=decode_content)
  File "/home/tamara/Sws/senpwai/.venv/lib/python3.13/site-packages/urllib3/response.py", line 980, in read
    data = self._raw_read(amt)
  File "/home/tamara/Sws/senpwai/.venv/lib/python3.13/site-packages/urllib3/response.py", line 903, in _raw_read
    with self._error_catcher():
         ~~~~~~~~~~~~~~~~~~~^^
  File "/usr/lib/python3.13/contextlib.py", line 162, in __exit__
    self.gen.throw(value)
    ~~~~~~~~~~~~~~^^^^^^^
  File "/home/tamara/Sws/senpwai/.venv/lib/python3.13/site-packages/urllib3/response.py", line 806, in _error_catcher
    raise ProtocolError(f"Connection broken: {e!r}", e) from e
urllib3.exceptions.ProtocolError: ("Connection broken: ConnectionResetError(104, 'Connection reset by peer')", ConnectionResetError(104, 'Connection reset by peer'))

During handling of the above exception, another exception occurred:

Traceback (most recent call last):
  File "/home/tamara/Sws/senpwai/.venv/lib/python3.13/site-packages/senpwai/common/scraper.py", line 229, in network_error_retry_wrapper
    return callback()
  File "/home/tamara/Sws/senpwai/.venv/lib/python3.13/site-packages/senpwai/common/scraper.py", line 558, in <lambda>
    lambda: next(iter_content)
            ~~~~^^^^^^^^^^^^^^
  File "/home/tamara/Sws/senpwai/.venv/lib/python3.13/site-packages/requests/models.py", line 822, in generate
    raise ChunkedEncodingError(e)
requests.exceptions.ChunkedEncodingError: ("Connection broken: ConnectionResetError(104, 'Connection reset by peer')", ConnectionResetError(104, 'Connection reset by peer'))
-----------------------------------------------------------------------------------------------------------------------------

2025-07-10 19:59:32,176 - ERROR - Exception: Traceback (most recent call last):
  File "/home/tamara/Sws/senpwai/.venv/lib/python3.13/site-packages/urllib3/response.py", line 779, in _error_catcher
    yield
  File "/home/tamara/Sws/senpwai/.venv/lib/python3.13/site-packages/urllib3/response.py", line 904, in _raw_read
    data = self._fp_read(amt, read1=read1) if not fp_closed else b""
           ~~~~~~~~~~~~~^^^^^^^^^^^^^^^^^^
  File "/home/tamara/Sws/senpwai/.venv/lib/python3.13/site-packages/urllib3/response.py", line 887, in _fp_read
    return self._fp.read(amt) if amt is not None else self._fp.read()
           ~~~~~~~~~~~~~^^^^^
  File "/usr/lib/python3.13/http/client.py", line 479, in read
    s = self.fp.read(amt)
  File "/usr/lib/python3.13/socket.py", line 719, in readinto
    return self._sock.recv_into(b)
           ~~~~~~~~~~~~~~~~~~~~^^^
  File "/usr/lib/python3.13/ssl.py", line 1304, in recv_into
    return self.read(nbytes, buffer)
           ~~~~~~~~~^^^^^^^^^^^^^^^^
  File "/usr/lib/python3.13/ssl.py", line 1138, in read
    return self._sslobj.read(len, buffer)
           ~~~~~~~~~~~~~~~~~^^^^^^^^^^^^^
ConnectionResetError: [Errno 104] Connection reset by peer

The above exception was the direct cause of the following exception:

Traceback (most recent call last):
  File "/home/tamara/Sws/senpwai/.venv/lib/python3.13/site-packages/requests/models.py", line 820, in generate
    yield from self.raw.stream(chunk_size, decode_content=True)
  File "/home/tamara/Sws/senpwai/.venv/lib/python3.13/site-packages/urllib3/response.py", line 1091, in stream
    data = self.read(amt=amt, decode_content=decode_content)
  File "/home/tamara/Sws/senpwai/.venv/lib/python3.13/site-packages/urllib3/response.py", line 980, in read
    data = self._raw_read(amt)
  File "/home/tamara/Sws/senpwai/.venv/lib/python3.13/site-packages/urllib3/response.py", line 903, in _raw_read
    with self._error_catcher():
         ~~~~~~~~~~~~~~~~~~~^^
  File "/usr/lib/python3.13/contextlib.py", line 162, in __exit__
    self.gen.throw(value)
    ~~~~~~~~~~~~~~^^^^^^^
  File "/home/tamara/Sws/senpwai/.venv/lib/python3.13/site-packages/urllib3/response.py", line 806, in _error_catcher
    raise ProtocolError(f"Connection broken: {e!r}", e) from e
urllib3.exceptions.ProtocolError: ("Connection broken: ConnectionResetError(104, 'Connection reset by peer')", ConnectionResetError(104, 'Connection reset by peer'))

During handling of the above exception, another exception occurred:

Traceback (most recent call last):
  File "/home/tamara/Sws/senpwai/.venv/lib/python3.13/site-packages/senpwai/common/scraper.py", line 229, in network_error_retry_wrapper
    return callback()
  File "/home/tamara/Sws/senpwai/.venv/lib/python3.13/site-packages/senpwai/common/scraper.py", line 558, in <lambda>
    lambda: next(iter_content)
            ~~~~^^^^^^^^^^^^^^
  File "/home/tamara/Sws/senpwai/.venv/lib/python3.13/site-packages/requests/models.py", line 822, in generate
    raise ChunkedEncodingError(e)
requests.exceptions.ChunkedEncodingError: ("Connection broken: ConnectionResetError(104, 'Connection reset by peer')", ConnectionResetError(104, 'Connection reset by peer'))
-----------------------------------------------------------------------------------------------------------------------------

2025-07-10 20:16:05,958 - ERROR - Exception: Traceback (most recent call last):
  File "/home/tamara/Sws/senpwai/.venv/lib/python3.13/site-packages/urllib3/response.py", line 779, in _error_catcher
    yield
  File "/home/tamara/Sws/senpwai/.venv/lib/python3.13/site-packages/urllib3/response.py", line 904, in _raw_read
    data = self._fp_read(amt, read1=read1) if not fp_closed else b""
           ~~~~~~~~~~~~~^^^^^^^^^^^^^^^^^^
  File "/home/tamara/Sws/senpwai/.venv/lib/python3.13/site-packages/urllib3/response.py", line 887, in _fp_read
    return self._fp.read(amt) if amt is not None else self._fp.read()
           ~~~~~~~~~~~~~^^^^^
  File "/usr/lib/python3.13/http/client.py", line 479, in read
    s = self.fp.read(amt)
  File "/usr/lib/python3.13/socket.py", line 719, in readinto
    return self._sock.recv_into(b)
           ~~~~~~~~~~~~~~~~~~~~^^^
  File "/usr/lib/python3.13/ssl.py", line 1304, in recv_into
    return self.read(nbytes, buffer)
           ~~~~~~~~~^^^^^^^^^^^^^^^^
  File "/usr/lib/python3.13/ssl.py", line 1138, in read
    return self._sslobj.read(len, buffer)
           ~~~~~~~~~~~~~~~~~^^^^^^^^^^^^^
ConnectionResetError: [Errno 104] Connection reset by peer

The above exception was the direct cause of the following exception:

Traceback (most recent call last):
  File "/home/tamara/Sws/senpwai/.venv/lib/python3.13/site-packages/requests/models.py", line 820, in generate
    yield from self.raw.stream(chunk_size, decode_content=True)
  File "/home/tamara/Sws/senpwai/.venv/lib/python3.13/site-packages/urllib3/response.py", line 1091, in stream
    data = self.read(amt=amt, decode_content=decode_content)
  File "/home/tamara/Sws/senpwai/.venv/lib/python3.13/site-packages/urllib3/response.py", line 980, in read
    data = self._raw_read(amt)
  File "/home/tamara/Sws/senpwai/.venv/lib/python3.13/site-packages/urllib3/response.py", line 903, in _raw_read
    with self._error_catcher():
         ~~~~~~~~~~~~~~~~~~~^^
  File "/usr/lib/python3.13/contextlib.py", line 162, in __exit__
    self.gen.throw(value)
    ~~~~~~~~~~~~~~^^^^^^^
  File "/home/tamara/Sws/senpwai/.venv/lib/python3.13/site-packages/urllib3/response.py", line 806, in _error_catcher
    raise ProtocolError(f"Connection broken: {e!r}", e) from e
urllib3.exceptions.ProtocolError: ("Connection broken: ConnectionResetError(104, 'Connection reset by peer')", ConnectionResetError(104, 'Connection reset by peer'))

During handling of the above exception, another exception occurred:

Traceback (most recent call last):
  File "/home/tamara/Sws/senpwai/.venv/lib/python3.13/site-packages/senpwai/common/scraper.py", line 229, in network_error_retry_wrapper
    return callback()
  File "/home/tamara/Sws/senpwai/.venv/lib/python3.13/site-packages/senpwai/common/scraper.py", line 558, in <lambda>
    lambda: next(iter_content)
            ~~~~^^^^^^^^^^^^^^
  File "/home/tamara/Sws/senpwai/.venv/lib/python3.13/site-packages/requests/models.py", line 822, in generate
    raise ChunkedEncodingError(e)
requests.exceptions.ChunkedEncodingError: ("Connection broken: ConnectionResetError(104, 'Connection reset by peer')", ConnectionResetError(104, 'Connection reset by peer'))
-----------------------------------------------------------------------------------------------------------------------------

2025-07-10 20:28:17,735 - ERROR - Exception: Traceback (most recent call last):
  File "/home/tamara/Sws/senpwai/.venv/lib/python3.13/site-packages/urllib3/response.py", line 779, in _error_catcher
    yield
  File "/home/tamara/Sws/senpwai/.venv/lib/python3.13/site-packages/urllib3/response.py", line 904, in _raw_read
    data = self._fp_read(amt, read1=read1) if not fp_closed else b""
           ~~~~~~~~~~~~~^^^^^^^^^^^^^^^^^^
  File "/home/tamara/Sws/senpwai/.venv/lib/python3.13/site-packages/urllib3/response.py", line 887, in _fp_read
    return self._fp.read(amt) if amt is not None else self._fp.read()
           ~~~~~~~~~~~~~^^^^^
  File "/usr/lib/python3.13/http/client.py", line 479, in read
    s = self.fp.read(amt)
  File "/usr/lib/python3.13/socket.py", line 719, in readinto
    return self._sock.recv_into(b)
           ~~~~~~~~~~~~~~~~~~~~^^^
  File "/usr/lib/python3.13/ssl.py", line 1304, in recv_into
    return self.read(nbytes, buffer)
           ~~~~~~~~~^^^^^^^^^^^^^^^^
  File "/usr/lib/python3.13/ssl.py", line 1138, in read
    return self._sslobj.read(len, buffer)
           ~~~~~~~~~~~~~~~~~^^^^^^^^^^^^^
ConnectionResetError: [Errno 104] Connection reset by peer

The above exception was the direct cause of the following exception:

Traceback (most recent call last):
  File "/home/tamara/Sws/senpwai/.venv/lib/python3.13/site-packages/requests/models.py", line 820, in generate
    yield from self.raw.stream(chunk_size, decode_content=True)
  File "/home/tamara/Sws/senpwai/.venv/lib/python3.13/site-packages/urllib3/response.py", line 1091, in stream
    data = self.read(amt=amt, decode_content=decode_content)
  File "/home/tamara/Sws/senpwai/.venv/lib/python3.13/site-packages/urllib3/response.py", line 980, in read
    data = self._raw_read(amt)
  File "/home/tamara/Sws/senpwai/.venv/lib/python3.13/site-packages/urllib3/response.py", line 903, in _raw_read
    with self._error_catcher():
         ~~~~~~~~~~~~~~~~~~~^^
  File "/usr/lib/python3.13/contextlib.py", line 162, in __exit__
    self.gen.throw(value)
    ~~~~~~~~~~~~~~^^^^^^^
  File "/home/tamara/Sws/senpwai/.venv/lib/python3.13/site-packages/urllib3/response.py", line 806, in _error_catcher
    raise ProtocolError(f"Connection broken: {e!r}", e) from e
urllib3.exceptions.ProtocolError: ("Connection broken: ConnectionResetError(104, 'Connection reset by peer')", ConnectionResetError(104, 'Connection reset by peer'))

During handling of the above exception, another exception occurred:

Traceback (most recent call last):
  File "/home/tamara/Sws/senpwai/.venv/lib/python3.13/site-packages/senpwai/common/scraper.py", line 229, in network_error_retry_wrapper
    return callback()
  File "/home/tamara/Sws/senpwai/.venv/lib/python3.13/site-packages/senpwai/common/scraper.py", line 558, in <lambda>
    lambda: next(iter_content)
            ~~~~^^^^^^^^^^^^^^
  File "/home/tamara/Sws/senpwai/.venv/lib/python3.13/site-packages/requests/models.py", line 822, in generate
    raise ChunkedEncodingError(e)
requests.exceptions.ChunkedEncodingError: ("Connection broken: ConnectionResetError(104, 'Connection reset by peer')", ConnectionResetError(104, 'Connection reset by peer'))
-----------------------------------------------------------------------------------------------------------------------------

2025-07-10 20:35:14,855 - ERROR - Exception: Traceback (most recent call last):
  File "/home/tamara/Sws/senpwai/.venv/lib/python3.13/site-packages/urllib3/response.py", line 779, in _error_catcher
    yield
  File "/home/tamara/Sws/senpwai/.venv/lib/python3.13/site-packages/urllib3/response.py", line 904, in _raw_read
    data = self._fp_read(amt, read1=read1) if not fp_closed else b""
           ~~~~~~~~~~~~~^^^^^^^^^^^^^^^^^^
  File "/home/tamara/Sws/senpwai/.venv/lib/python3.13/site-packages/urllib3/response.py", line 887, in _fp_read
    return self._fp.read(amt) if amt is not None else self._fp.read()
           ~~~~~~~~~~~~~^^^^^
  File "/usr/lib/python3.13/http/client.py", line 479, in read
    s = self.fp.read(amt)
  File "/usr/lib/python3.13/socket.py", line 719, in readinto
    return self._sock.recv_into(b)
           ~~~~~~~~~~~~~~~~~~~~^^^
  File "/usr/lib/python3.13/ssl.py", line 1304, in recv_into
    return self.read(nbytes, buffer)
           ~~~~~~~~~^^^^^^^^^^^^^^^^
  File "/usr/lib/python3.13/ssl.py", line 1138, in read
    return self._sslobj.read(len, buffer)
           ~~~~~~~~~~~~~~~~~^^^^^^^^^^^^^
TimeoutError: The read operation timed out

The above exception was the direct cause of the following exception:

Traceback (most recent call last):
  File "/home/tamara/Sws/senpwai/.venv/lib/python3.13/site-packages/requests/models.py", line 820, in generate
    yield from self.raw.stream(chunk_size, decode_content=True)
  File "/home/tamara/Sws/senpwai/.venv/lib/python3.13/site-packages/urllib3/response.py", line 1091, in stream
    data = self.read(amt=amt, decode_content=decode_content)
  File "/home/tamara/Sws/senpwai/.venv/lib/python3.13/site-packages/urllib3/response.py", line 980, in read
    data = self._raw_read(amt)
  File "/home/tamara/Sws/senpwai/.venv/lib/python3.13/site-packages/urllib3/response.py", line 903, in _raw_read
    with self._error_catcher():
         ~~~~~~~~~~~~~~~~~~~^^
  File "/usr/lib/python3.13/contextlib.py", line 162, in __exit__
    self.gen.throw(value)
    ~~~~~~~~~~~~~~^^^^^^^
  File "/home/tamara/Sws/senpwai/.venv/lib/python3.13/site-packages/urllib3/response.py", line 784, in _error_catcher
    raise ReadTimeoutError(self._pool, None, "Read timed out.") from e  # type: ignore[arg-type]
    ^^^^^^^^^^^^^^^^^^^^^^^^^^^^^^^^^^^^^^^^^^^^^^^^^^^^^^^^^^^^^^^^^^
urllib3.exceptions.ReadTimeoutError: HTTPSConnectionPool(host='eu-03.nextcdn.org', port=443): Read timed out.

During handling of the above exception, another exception occurred:

Traceback (most recent call last):
  File "/home/tamara/Sws/senpwai/.venv/lib/python3.13/site-packages/senpwai/common/scraper.py", line 229, in network_error_retry_wrapper
    return callback()
  File "/home/tamara/Sws/senpwai/.venv/lib/python3.13/site-packages/senpwai/common/scraper.py", line 558, in <lambda>
    lambda: next(iter_content)
            ~~~~^^^^^^^^^^^^^^
  File "/home/tamara/Sws/senpwai/.venv/lib/python3.13/site-packages/requests/models.py", line 826, in generate
    raise ConnectionError(e)
requests.exceptions.ConnectionError: HTTPSConnectionPool(host='eu-03.nextcdn.org', port=443): Read timed out.
-----------------------------------------------------------------------------------------------------------------------------

